Workbook

Sheet Arrays
A1: Description | B1: Formula | C1: Result | E1: Expected
A2: CHOOSECOLS: sum of columns 1 and 3 | B2: =SUM(CHOOSECOLS(Data!A2:D7,1,3)) | C2: {=SUM(_xlfn.CHOOSECOLS(Data!A2:D7,1,3))} -> 144 | E2: 144
A3: CHOOSECOLS: last column, negative index | B3: =SUM(CHOOSECOLS(Data!A2:D7,-1)) | C3: {=SUM(_xlfn.CHOOSECOLS(Data!A2:D7,-1))} -> 84 | E3: 84
A4: CHOOSECOLS: index 0 | B4: =CHOOSECOLS(Data!A2:D7,0) | C4: {=_xlfn.CHOOSECOLS(Data!A2:D7,0)} -> #VALUE! | E4: #VALUE!
A5: CHOOSECOLS: index beyond the array | B5: =CHOOSECOLS(Data!A2:D7,5) | C5: {=_xlfn.CHOOSECOLS(Data!A2:D7,5)} -> #VALUE! | E5: #VALUE!
A6: CHOOSEROWS: rows 1,3,5 and 1 (count) | B6: =ROWS(CHOOSEROWS(Data!A2:D7,1,3,5,1)) | C6: {=ROWS(_xlfn.CHOOSEROWS(Data!A2:D7,1,3,5,1))} -> 4 | E6: 4
A7: CHOOSEROWS: array of indexes | B7: =SUM(CHOOSEROWS(Data!A2:D7,{1,3})) | C7: {=SUM(_xlfn.CHOOSEROWS(Data!A2:D7,{1,3}))} -> 52 | E7: 52
A8: CHOOSEROWS: second to last row | B8: =INDEX(CHOOSEROWS(Data!A2:D7,-2),1,1) | C8: {=INDEX(_xlfn.CHOOSEROWS(Data!A2:D7,-2),1,1)} -> 17 | E8: 17
A9: CHOOSEROWS: index beyond the array | B9: =CHOOSEROWS(Data!A2:D7,7) | C9: {=_xlfn.CHOOSEROWS(Data!A2:D7,7)} -> #VALUE! | E9: #VALUE!
A10: TAKE: first 2 rows (sum) | B10: =SUM(TAKE(Data!F2:H4,2)) | C10: {=SUM(_xlfn.TAKE(Data!F2:H4,2))} -> 21 | E10: 21
A11: TAKE: last 2 columns (sum) | B11: =SUM(TAKE(Data!F2:H4,,-2)) | C11: {=SUM(_xlfn.TAKE(Data!F2:H4,,-2))} -> 33 | E11: 33
A12: TAKE: 0 rows | B12: =TAKE(Data!F2:H4,0) | C12: {=_xlfn.TAKE(Data!F2:H4,0)} -> #CALC! | E12: #CALC!
A13: TAKE: more rows than there are | B13: =ROWS(TAKE(Data!F2:H4,10)) | C13: {=ROWS(_xlfn.TAKE(Data!F2:H4,10))} -> 3 | E13: 3
A14: TAKE: last cell of a column | B14: =TAKE(Data!F2:F4,-1) | C14: {=_xlfn.TAKE(Data!F2:F4,-1)} -> 7 | E14: 7
A15: DROP: first 2 rows dropped | B15: =SUM(DROP(Data!F2:H4,2)) | C15: {=SUM(_xlfn.DROP(Data!F2:H4,2))} -> 24 | E15: 24
A16: DROP: 2 rows and 2 columns dropped | B16: =DROP(Data!F2:H4,2,2) | C16: {=_xlfn.DROP(Data!F2:H4,2,2)} -> 9 | E16: 9
A17: DROP: last 2 rows dropped | B17: =SUM(DROP(Data!F2:H4,-2)) | C17: {=SUM(_xlfn.DROP(Data!F2:H4,-2))} -> 6 | E17: 6
A18: DROP: everything dropped | B18: =DROP(Data!F2:H4,3) | C18: {=_xlfn.DROP(Data!F2:H4,3)} -> #CALC! | E18: #CALC!
A19: EXPAND: padded cell is #N/A | B19: =INDEX(EXPAND({1,2;3,4},3,3),3,3) | C19: {=INDEX(_xlfn.EXPAND({1,2;3,4},3,3),3,3)} -> #N/A | E19: #N/A
A20: EXPAND: pad_with | B20: =INDEX(EXPAND({1,2;3,4},3,3,"-"),1,3) | C20: {=INDEX(_xlfn.EXPAND({1,2;3,4},3,3,"-"),1,3)} -> - | E20: -
A21: EXPAND: smaller than the array | B21: =EXPAND({1,2;3,4},1,2) | C21: {=_xlfn.EXPAND({1,2;3,4},1,2)} -> #VALUE! | E21: #VALUE!
A22: HSTACK: width of 3+3 | B22: =COLUMNS(HSTACK({"A","B","C"},{"AA","BB","CC"})) | C22: {=COLUMNS(_xlfn.HSTACK({"A","B","C"},{"AA","BB","CC"}))} -> 6 | E22: 6
A23: VSTACK: ragged input padded with #N/A | B23: =INDEX(VSTACK({1,2},{3;4}),3,2) | C23: {=INDEX(_xlfn.VSTACK({1,2},{3;4}),3,2)} -> #N/A | E23: #N/A
A24: VSTACK of two ranges (sum) | B24: =SUM(VSTACK(Data!F2:H2,Data!F4:H4)) | C24: {=SUM(_xlfn.VSTACK(Data!F2:H2,Data!F4:H4))} -> 30 | E24: 30
A25: TOCOL: count, blanks kept | B25: =ROWS(TOCOL(Data!J2:M4)) | C25: {=ROWS(_xlfn.TOCOL(Data!J2:M4))} -> 12 | E25: 12
A26: TOCOL: ignore blanks and errors | B26: =ROWS(TOCOL(Data!J2:M4,3)) | C26: {=ROWS(_xlfn.TOCOL(Data!J2:M4,3))} -> 10 | E26: 10
A27: TOCOL: scan by column, 2nd value | B27: =INDEX(TOCOL(Data!J2:M4,3,TRUE),2) | C27: {=INDEX(_xlfn.TOCOL(Data!J2:M4,3,TRUE),2)} -> John | E27: John
A28: TOROW: by row, 2nd value | B28: =INDEX(TOROW(Data!J2:M4),2) | C28: {=INDEX(_xlfn.TOROW(Data!J2:M4),2)} -> Peter | E28: Peter
A29: TOROW: invalid ignore | B29: =TOROW(Data!J2:M4,4) | C29: {=_xlfn.TOROW(Data!J2:M4,4)} -> #VALUE! | E29: #VALUE!
A30: WRAPROWS: 7 values in rows of 3 | B30: =ROWS(WRAPROWS(SEQUENCE(1,7),3)) | C30: {=ROWS(_xlfn.WRAPROWS(_xlfn.SEQUENCE(1,7),3))} -> 3 | E30: 3
A31: WRAPROWS: padding #N/A | B31: =INDEX(WRAPROWS(SEQUENCE(1,7),3),3,2) | C31: {=INDEX(_xlfn.WRAPROWS(_xlfn.SEQUENCE(1,7),3),3,2)} -> #N/A | E31: #N/A
A32: WRAPCOLS: pad_with 0 (sum) | B32: =SUM(WRAPCOLS(SEQUENCE(7),3,0)) | C32: {=SUM(_xlfn.WRAPCOLS(_xlfn.SEQUENCE(7),3,0))} -> 28 | E32: 28
A33: WRAPROWS: 2-D input | B33: =WRAPROWS({1,2;3,4},2) | C33: {=_xlfn.WRAPROWS({1,2;3,4},2)} -> #VALUE! | E33: #VALUE!
A34: WRAPROWS: wrap_count 0 | B34: =WRAPROWS({1,2,3},0) | C34: {=_xlfn.WRAPROWS({1,2,3},0)} -> #NUM! | E34: #NUM!
A35: TRIMRANGE: whole column O trimmed | B35: =ROWS(TRIMRANGE(Data!O:O)) | C35: {=ROWS(_xlfn.TRIMRANGE(Data!O:O))} -> 4 | E35: 4
A36: TRIMRANGE: first row of O:O | B36: =MIN(ROW(TRIMRANGE(Data!O:O))) | C36: {=MIN(ROW(_xlfn.TRIMRANGE(Data!O:O)))} -> 3 | E36: 3
A37: TRIMRANGE: leading rows only | B37: =ROWS(TRIMRANGE(Data!O1:O20,1)) | C37: {=ROWS(_xlfn.TRIMRANGE(Data!O1:O20,1))} -> 18 | E37: 18
A38: TRIMRANGE: trailing rows only | B38: =ROWS(TRIMRANGE(Data!O1:O20,2)) | C38: {=ROWS(_xlfn.TRIMRANGE(Data!O1:O20,2))} -> 6 | E38: 6
A39: TRIMRANGE: sum of trimmed column | B39: =SUM(TRIMRANGE(Data!O:O)) | C39: {=SUM(_xlfn.TRIMRANGE(Data!O:O))} -> 15 | E39: 15
A40: TRIMRANGE: empty range | B40: =TRIMRANGE(Data!Q1:Q5) | C40: {=_xlfn.TRIMRANGE(Data!Q1:Q5)} -> #REF! | E40: #REF!
...

Sheet Spills
A1: Result (spilled) | J1: Expected
A3: CHOOSECOLS columns 1 and 3: =CHOOSECOLS(Data!A2:D7,1,3)
A4: {=_xlfn.CHOOSECOLS(Data!A2:D7,1,3)} -> 1 | B4: 3 | J4: 1 | K4: 3
A5: 5 | B5: 7 | J5: 5 | K5: 7
A6: 9 | B6: 11 | J6: 9 | K6: 11
A7: 13 | B7: 15 | J7: 13 | K7: 15
A8: 17 | B8: 19 | J8: 17 | K8: 19
A9: 21 | B9: 23 | J9: 21 | K9: 23
A12: CHOOSEROWS rows 1,3,5,1: =CHOOSEROWS(Data!A2:D7,1,3,5,1)
A13: {=_xlfn.CHOOSEROWS(Data!A2:D7,1,3,5,1)} -> 1 | B13: 2 | C13: 3 | D13: 4 | J13: 1 | K13: 2 | L13: 3 | M13: 4
A14: 9 | B14: 10 | C14: 11 | D14: 12 | J14: 9 | K14: 10 | L14: 11 | M14: 12
A15: 17 | B15: 18 | C15: 19 | D15: 20 | J15: 17 | K15: 18 | L15: 19 | M15: 20
A16: 1 | B16: 2 | C16: 3 | D16: 4 | J16: 1 | K16: 2 | L16: 3 | M16: 4
A19: TAKE first 2 rows: =TAKE(Data!F2:H4,2)
A20: {=_xlfn.TAKE(Data!F2:H4,2)} -> 1 | B20: 2 | C20: 3 | J20: 1 | K20: 2 | L20: 3
A21: 4 | B21: 5 | C21: 6 | J21: 4 | K21: 5 | L21: 6
A24: TAKE last 2 rows, first 2 columns: =TAKE(Data!F2:H4,-2,2)
A25: {=_xlfn.TAKE(Data!F2:H4,-2,2)} -> 4 | B25: 5 | J25: 4 | K25: 5
A26: 7 | B26: 8 | J26: 7 | K26: 8
A29: DROP 2 columns: =DROP(Data!F2:H4,,2)
A30: {=_xlfn.DROP(Data!F2:H4,,2)} -> 3 | J30: 3
A31: 6 | J31: 6
A32: 9 | J32: 9
A35: EXPAND to 3x3 (#N/A): =EXPAND({1,2;3,4},3,3)
A36: {=_xlfn.EXPAND({1,2;3,4},3,3)} -> 1 | B36: 2 | C36: #N/A | J36: 1 | K36: 2 | L36: #N/A
A37: 3 | B37: 4 | C37: #N/A | J37: 3 | K37: 4 | L37: #N/A
A38: #N/A | B38: #N/A | C38: #N/A | J38: #N/A | K38: #N/A | L38: #N/A
A41: HSTACK: =HSTACK({"A","B","C"},{"AA","BB","CC"})
A42: {=_xlfn.HSTACK({"A","B","C"},{"AA","BB","CC"})} -> A | B42: B | C42: C | D42: AA | E42: BB | F42: CC | J42: A | K42: B | L42: C | M42: AA | N42: BB | O42: CC
A45: VSTACK ragged: =VSTACK({1,2},{3;4})
A46: {=_xlfn.VSTACK({1,2},{3;4})} -> 1 | B46: 2 | J46: 1 | K46: 2
A47: 3 | B47: #N/A | J47: 3 | K47: #N/A
A48: 4 | B48: #N/A | J48: 4 | K48: #N/A
A51: TOCOL ignoring blanks and errors, by column: =TOCOL(Data!J2:M4,3,TRUE)
A52: {=_xlfn.TOCOL(Data!J2:M4,3,TRUE)} -> Ben | J52: Ben
A53: John | J53: John
A54: Agnes | J54: Agnes
A55: Peter | J55: Peter
A56: Hillary | J56: Hillary
A57: Harry | J57: Harry
...

Sheet Data
A1: CHOOSECOLS / CHOOSEROWS | F1: TAKE / DROP | J1: TOCOL / TOROW | P1: ← TRIMRANGE data in O3:O6
A2: 1 | B2: 2 | C2: 3 | D2: 4 | F2: 1 | G2: 2 | H2: 3 | J2: Ben | K2: Peter | L2: Mary | M2: Sam
A3: 5 | B3: 6 | C3: 7 | D3: 8 | F3: 4 | G3: 5 | H3: 6 | J3: John | K3: Hillary | L3: Jenny | M3: James | O3: 1
A4: 9 | B4: 10 | C4: 11 | D4: 12 | F4: 7 | G4: 8 | H4: 9 | J4: Agnes | K4: Harry | M4: #N/A | O4: 2
A5: 13 | B5: 14 | C5: 15 | D5: 16
A6: 17 | B6: 18 | C6: 19 | D6: 20 | O6: 12
A7: 21 | B7: 22 | C7: 23 | D7: 24
A9: GROUPBY / PIVOTBY
A10: Region | B10: Product | C10: Year | D10: Sales
A11: East | B11: A | C11: 2023 | D11: 10
A12: West | B12: B | C12: 2023 | D12: 20
A13: East | B13: B | C13: 2024 | D13: 30
A14: West | B14: A | C14: 2024 | D14: 40
A15: East | B15: A | C15: 2024 | D15: 50
